[2022-05-02 07:59:34,479] {taskinstance.py:1032} INFO - Dependencies all met for <TaskInstance: gcs_to_bq_dag.process_data_from_gcs_task manual__2022-05-02T07:59:28.874635+00:00 [queued]>
[2022-05-02 07:59:34,522] {taskinstance.py:1032} INFO - Dependencies all met for <TaskInstance: gcs_to_bq_dag.process_data_from_gcs_task manual__2022-05-02T07:59:28.874635+00:00 [queued]>
[2022-05-02 07:59:34,523] {taskinstance.py:1238} INFO - 
--------------------------------------------------------------------------------
[2022-05-02 07:59:34,524] {taskinstance.py:1239} INFO - Starting attempt 1 of 2
[2022-05-02 07:59:34,526] {taskinstance.py:1240} INFO - 
--------------------------------------------------------------------------------
[2022-05-02 07:59:34,574] {taskinstance.py:1259} INFO - Executing <Task(PythonOperator): process_data_from_gcs_task> on 2022-05-02 07:59:28.874635+00:00
[2022-05-02 07:59:34,584] {standard_task_runner.py:52} INFO - Started process 10387 to run task
[2022-05-02 07:59:34,593] {standard_task_runner.py:76} INFO - Running: ['***', 'tasks', 'run', 'gcs_to_bq_dag', 'process_data_from_gcs_task', 'manual__2022-05-02T07:59:28.874635+00:00', '--job-id', '919', '--raw', '--subdir', 'DAGS_FOLDER/gcs_to_bq_task.py', '--cfg-path', '/tmp/tmpavmo4v1s', '--error-file', '/tmp/tmphv223i7u']
[2022-05-02 07:59:34,596] {standard_task_runner.py:77} INFO - Job 919: Subtask process_data_from_gcs_task
[2022-05-02 07:59:34,979] {logging_mixin.py:109} INFO - Running <TaskInstance: gcs_to_bq_dag.process_data_from_gcs_task manual__2022-05-02T07:59:28.874635+00:00 [running]> on host ae42322ae538
[2022-05-02 07:59:35,476] {taskinstance.py:1426} INFO - Exporting the following env vars:
AIRFLOW_CTX_DAG_OWNER=***
AIRFLOW_CTX_DAG_ID=gcs_to_bq_dag
AIRFLOW_CTX_TASK_ID=process_data_from_gcs_task
AIRFLOW_CTX_EXECUTION_DATE=2022-05-02T07:59:28.874635+00:00
AIRFLOW_CTX_DAG_RUN_ID=manual__2022-05-02T07:59:28.874635+00:00
[2022-05-02 08:00:33,078] {local_task_job.py:212} WARNING - State of this instance has been externally set to failed. Terminating instance.
[2022-05-02 08:00:33,092] {process_utils.py:124} INFO - Sending Signals.SIGTERM to group 10387. PIDs of all processes in the group: [10391, 10387]
[2022-05-02 08:00:33,094] {process_utils.py:75} INFO - Sending the signal Signals.SIGTERM to group 10387
[2022-05-02 08:00:33,098] {taskinstance.py:1408} ERROR - Received SIGTERM. Terminating subprocesses.
[2022-05-02 08:00:33,101] {clientserver.py:502} INFO - Error while receiving.
Traceback (most recent call last):
  File "/home/airflow/.local/lib/python3.7/site-packages/py4j/clientserver.py", line 475, in send_command
    answer = smart_decode(self.stream.readline()[:-1])
  File "/usr/local/lib/python3.7/socket.py", line 589, in readinto
    return self._sock.recv_into(b)
  File "/home/airflow/.local/lib/python3.7/site-packages/airflow/models/taskinstance.py", line 1410, in signal_handler
    raise AirflowException("Task received SIGTERM signal")
airflow.exceptions.AirflowException: Task received SIGTERM signal
[2022-05-02 08:00:33,121] {clientserver.py:507} INFO - Closing down clientserver connection
[2022-05-02 08:00:33,124] {java_gateway.py:1056} ERROR - Exception while sending command.
Traceback (most recent call last):
  File "/home/airflow/.local/lib/python3.7/site-packages/py4j/clientserver.py", line 475, in send_command
    answer = smart_decode(self.stream.readline()[:-1])
  File "/usr/local/lib/python3.7/socket.py", line 589, in readinto
    return self._sock.recv_into(b)
  File "/home/airflow/.local/lib/python3.7/site-packages/airflow/models/taskinstance.py", line 1410, in signal_handler
    raise AirflowException("Task received SIGTERM signal")
airflow.exceptions.AirflowException: Task received SIGTERM signal

During handling of the above exception, another exception occurred:

Traceback (most recent call last):
  File "/home/airflow/.local/lib/python3.7/site-packages/py4j/java_gateway.py", line 1038, in send_command
    response = connection.send_command(command)
  File "/home/airflow/.local/lib/python3.7/site-packages/py4j/clientserver.py", line 504, in send_command
    "Error while sending or receiving", e, proto.ERROR_ON_RECEIVE)
py4j.protocol.Py4JNetworkError: Error while sending or receiving
[2022-05-02 08:00:33,134] {taskinstance.py:1700} ERROR - Task failed with exception
Traceback (most recent call last):
  File "/home/airflow/.local/lib/python3.7/site-packages/airflow/models/taskinstance.py", line 1329, in _run_raw_task
    self._execute_task_with_callbacks(context)
  File "/home/airflow/.local/lib/python3.7/site-packages/airflow/models/taskinstance.py", line 1455, in _execute_task_with_callbacks
    result = self._execute_task(context, self.task)
  File "/home/airflow/.local/lib/python3.7/site-packages/airflow/models/taskinstance.py", line 1511, in _execute_task
    result = execute_callable(context=context)
  File "/home/airflow/.local/lib/python3.7/site-packages/airflow/operators/python.py", line 174, in execute
    return_value = self.execute_callable()
  File "/home/airflow/.local/lib/python3.7/site-packages/airflow/operators/python.py", line 185, in execute_callable
    return self.python_callable(*self.op_args, **self.op_kwargs)
  File "/opt/airflow/dags/gcs_to_bq_task.py", line 94, in process_data
    spark = SparkSession.builder.master("local[*]").appName('de-project').getOrCreate()
  File "/home/airflow/.local/lib/python3.7/site-packages/pyspark/sql/session.py", line 228, in getOrCreate
    sc = SparkContext.getOrCreate(sparkConf)
  File "/home/airflow/.local/lib/python3.7/site-packages/pyspark/context.py", line 392, in getOrCreate
    SparkContext(conf=conf or SparkConf())
  File "/home/airflow/.local/lib/python3.7/site-packages/pyspark/context.py", line 147, in __init__
    conf, jsc, profiler_cls)
  File "/home/airflow/.local/lib/python3.7/site-packages/pyspark/context.py", line 209, in _do_init
    self._jsc = jsc or self._initialize_context(self._conf._jconf)
  File "/home/airflow/.local/lib/python3.7/site-packages/pyspark/context.py", line 329, in _initialize_context
    return self._jvm.JavaSparkContext(jconf)
  File "/home/airflow/.local/lib/python3.7/site-packages/py4j/java_gateway.py", line 1586, in __call__
    answer, self._gateway_client, None, self._fqn)
  File "/home/airflow/.local/lib/python3.7/site-packages/py4j/protocol.py", line 336, in get_return_value
    format(target_id, ".", name))
py4j.protocol.Py4JError: An error occurred while calling None.org.apache.spark.api.java.JavaSparkContext
[2022-05-02 08:00:33,265] {taskinstance.py:1277} INFO - Marking task as FAILED. dag_id=gcs_to_bq_dag, task_id=process_data_from_gcs_task, execution_date=20220502T075928, start_date=20220502T075934, end_date=20220502T080033
[2022-05-02 08:00:33,330] {standard_task_runner.py:92} ERROR - Failed to execute job 919 for task process_data_from_gcs_task
Traceback (most recent call last):
  File "/home/airflow/.local/lib/python3.7/site-packages/airflow/task/task_runner/standard_task_runner.py", line 85, in _start_by_fork
    args.func(args, dag=self.dag)
  File "/home/airflow/.local/lib/python3.7/site-packages/airflow/cli/cli_parser.py", line 48, in command
    return func(*args, **kwargs)
  File "/home/airflow/.local/lib/python3.7/site-packages/airflow/utils/cli.py", line 92, in wrapper
    return f(*args, **kwargs)
  File "/home/airflow/.local/lib/python3.7/site-packages/airflow/cli/commands/task_command.py", line 298, in task_run
    _run_task_by_selected_method(args, dag, ti)
  File "/home/airflow/.local/lib/python3.7/site-packages/airflow/cli/commands/task_command.py", line 107, in _run_task_by_selected_method
    _run_raw_task(args, ti)
  File "/home/airflow/.local/lib/python3.7/site-packages/airflow/cli/commands/task_command.py", line 184, in _run_raw_task
    error_file=args.error_file,
  File "/home/airflow/.local/lib/python3.7/site-packages/airflow/utils/session.py", line 70, in wrapper
    return func(*args, session=session, **kwargs)
  File "/home/airflow/.local/lib/python3.7/site-packages/airflow/models/taskinstance.py", line 1329, in _run_raw_task
    self._execute_task_with_callbacks(context)
  File "/home/airflow/.local/lib/python3.7/site-packages/airflow/models/taskinstance.py", line 1455, in _execute_task_with_callbacks
    result = self._execute_task(context, self.task)
  File "/home/airflow/.local/lib/python3.7/site-packages/airflow/models/taskinstance.py", line 1511, in _execute_task
    result = execute_callable(context=context)
  File "/home/airflow/.local/lib/python3.7/site-packages/airflow/operators/python.py", line 174, in execute
    return_value = self.execute_callable()
  File "/home/airflow/.local/lib/python3.7/site-packages/airflow/operators/python.py", line 185, in execute_callable
    return self.python_callable(*self.op_args, **self.op_kwargs)
  File "/opt/airflow/dags/gcs_to_bq_task.py", line 94, in process_data
    spark = SparkSession.builder.master("local[*]").appName('de-project').getOrCreate()
  File "/home/airflow/.local/lib/python3.7/site-packages/pyspark/sql/session.py", line 228, in getOrCreate
    sc = SparkContext.getOrCreate(sparkConf)
  File "/home/airflow/.local/lib/python3.7/site-packages/pyspark/context.py", line 392, in getOrCreate
    SparkContext(conf=conf or SparkConf())
  File "/home/airflow/.local/lib/python3.7/site-packages/pyspark/context.py", line 147, in __init__
    conf, jsc, profiler_cls)
  File "/home/airflow/.local/lib/python3.7/site-packages/pyspark/context.py", line 209, in _do_init
    self._jsc = jsc or self._initialize_context(self._conf._jconf)
  File "/home/airflow/.local/lib/python3.7/site-packages/pyspark/context.py", line 329, in _initialize_context
    return self._jvm.JavaSparkContext(jconf)
  File "/home/airflow/.local/lib/python3.7/site-packages/py4j/java_gateway.py", line 1586, in __call__
    answer, self._gateway_client, None, self._fqn)
  File "/home/airflow/.local/lib/python3.7/site-packages/py4j/protocol.py", line 336, in get_return_value
    format(target_id, ".", name))
py4j.protocol.Py4JError: An error occurred while calling None.org.apache.spark.api.java.JavaSparkContext
[2022-05-02 08:00:33,605] {process_utils.py:70} INFO - Process psutil.Process(pid=10387, status='terminated', exitcode=1, started='07:59:33') (10387) terminated with exit code 1
[2022-05-02 08:01:33,130] {process_utils.py:138} WARNING - process psutil.Process(pid=10391, name='java', status='sleeping', started='07:59:34') did not respond to SIGTERM. Trying SIGKILL
[2022-05-02 08:01:33,137] {process_utils.py:75} INFO - Sending the signal Signals.SIGKILL to group 10387
[2022-05-02 08:01:33,485] {process_utils.py:70} INFO - Process psutil.Process(pid=10391, name='java', status='terminated', started='07:59:34') (10391) terminated with exit code None
