[2022-04-28 05:36:08,689] {taskinstance.py:1043} INFO - Dependencies all met for <TaskInstance: data_ingestion_gcp_dag.format_xl_to_csv_task scheduled__1991-01-01T00:00:00+00:00 [queued]>
[2022-04-28 05:36:08,734] {taskinstance.py:1043} INFO - Dependencies all met for <TaskInstance: data_ingestion_gcp_dag.format_xl_to_csv_task scheduled__1991-01-01T00:00:00+00:00 [queued]>
[2022-04-28 05:36:08,736] {taskinstance.py:1249} INFO - 
--------------------------------------------------------------------------------
[2022-04-28 05:36:08,738] {taskinstance.py:1250} INFO - Starting attempt 2 of 2
[2022-04-28 05:36:08,740] {taskinstance.py:1251} INFO - 
--------------------------------------------------------------------------------
[2022-04-28 05:36:08,787] {taskinstance.py:1270} INFO - Executing <Task(PythonOperator): format_xl_to_csv_task> on 1991-01-01 00:00:00+00:00
[2022-04-28 05:36:08,796] {standard_task_runner.py:52} INFO - Started process 6103 to run task
[2022-04-28 05:36:08,806] {standard_task_runner.py:79} INFO - Running: ['***', 'tasks', 'run', 'data_ingestion_gcp_dag', 'format_xl_to_csv_task', 'scheduled__1991-01-01T00:00:00+00:00', '--job-id', '449', '--raw', '--subdir', 'DAGS_FOLDER/ingest_to_gcs_dag.py', '--cfg-path', '/tmp/tmppzd2w1id', '--error-file', '/tmp/tmpb502hwlt']
[2022-04-28 05:36:08,809] {standard_task_runner.py:80} INFO - Job 449: Subtask format_xl_to_csv_task
[2022-04-28 05:36:09,174] {logging_mixin.py:109} INFO - Running <TaskInstance: data_ingestion_gcp_dag.format_xl_to_csv_task scheduled__1991-01-01T00:00:00+00:00 [running]> on host 65f5b8b3c17c
[2022-04-28 05:36:09,437] {logging_mixin.py:109} WARNING - /home/***/.local/lib/python3.7/site-packages/***/utils/context.py:156 AirflowContextDeprecationWarning: Accessing 'execution_date' from the template is deprecated and will be removed in a future version. Please use 'data_interval_start' or 'logical_date' instead.
[2022-04-28 05:36:09,621] {taskinstance.py:1448} INFO - Exporting the following env vars:
AIRFLOW_CTX_DAG_OWNER=***
AIRFLOW_CTX_DAG_ID=data_ingestion_gcp_dag
AIRFLOW_CTX_TASK_ID=format_xl_to_csv_task
AIRFLOW_CTX_EXECUTION_DATE=1991-01-01T00:00:00+00:00
AIRFLOW_CTX_DAG_RUN_ID=scheduled__1991-01-01T00:00:00+00:00
[2022-04-28 05:36:15,007] {taskinstance.py:1774} ERROR - Task failed with exception
Traceback (most recent call last):
  File "/home/airflow/.local/lib/python3.7/site-packages/airflow/operators/python.py", line 174, in execute
    return_value = self.execute_callable()
  File "/home/airflow/.local/lib/python3.7/site-packages/airflow/operators/python.py", line 188, in execute_callable
    return self.python_callable(*self.op_args, **self.op_kwargs)
  File "/opt/airflow/dags/ingest_to_gcs_dag.py", line 58, in format_xl_to_csv
    df.to_csv(f"{AIRFLOW_HOME}/us_employment_{df.year(6)}.csv")
TypeError: 'Series' object is not callable
[2022-04-28 05:36:15,113] {taskinstance.py:1288} INFO - Marking task as FAILED. dag_id=data_ingestion_gcp_dag, task_id=format_xl_to_csv_task, execution_date=19910101T000000, start_date=20220428T053608, end_date=20220428T053615
[2022-04-28 05:36:15,169] {standard_task_runner.py:98} ERROR - Failed to execute job 449 for task format_xl_to_csv_task ('Series' object is not callable; 6103)
[2022-04-28 05:36:15,193] {local_task_job.py:154} INFO - Task exited with return code 1
[2022-04-28 05:36:15,541] {local_task_job.py:264} INFO - 0 downstream tasks scheduled from follow-on schedule check
