[2022-05-02 06:50:20,934] {taskinstance.py:1032} INFO - Dependencies all met for <TaskInstance: gcs_to_bq_dag.process_data_from_gcs_task manual__2022-05-02T03:24:48.721222+00:00 [queued]>
[2022-05-02 06:50:20,970] {taskinstance.py:1032} INFO - Dependencies all met for <TaskInstance: gcs_to_bq_dag.process_data_from_gcs_task manual__2022-05-02T03:24:48.721222+00:00 [queued]>
[2022-05-02 06:50:20,972] {taskinstance.py:1238} INFO - 
--------------------------------------------------------------------------------
[2022-05-02 06:50:20,973] {taskinstance.py:1239} INFO - Starting attempt 16 of 17
[2022-05-02 06:50:20,974] {taskinstance.py:1240} INFO - 
--------------------------------------------------------------------------------
[2022-05-02 06:50:21,015] {taskinstance.py:1259} INFO - Executing <Task(PythonOperator): process_data_from_gcs_task> on 2022-05-02 03:24:48.721222+00:00
[2022-05-02 06:50:21,024] {standard_task_runner.py:52} INFO - Started process 2498 to run task
[2022-05-02 06:50:21,032] {standard_task_runner.py:76} INFO - Running: ['***', 'tasks', 'run', 'gcs_to_bq_dag', 'process_data_from_gcs_task', 'manual__2022-05-02T03:24:48.721222+00:00', '--job-id', '817', '--raw', '--subdir', 'DAGS_FOLDER/gcs_to_bq_task.py', '--cfg-path', '/tmp/tmpk9ts8byu', '--error-file', '/tmp/tmpvgblztfu']
[2022-05-02 06:50:21,035] {standard_task_runner.py:77} INFO - Job 817: Subtask process_data_from_gcs_task
[2022-05-02 06:50:21,341] {logging_mixin.py:109} INFO - Running <TaskInstance: gcs_to_bq_dag.process_data_from_gcs_task manual__2022-05-02T03:24:48.721222+00:00 [running]> on host ae42322ae538
[2022-05-02 06:50:21,671] {taskinstance.py:1426} INFO - Exporting the following env vars:
AIRFLOW_CTX_DAG_OWNER=***
AIRFLOW_CTX_DAG_ID=gcs_to_bq_dag
AIRFLOW_CTX_TASK_ID=process_data_from_gcs_task
AIRFLOW_CTX_EXECUTION_DATE=2022-05-02T03:24:48.721222+00:00
AIRFLOW_CTX_DAG_RUN_ID=manual__2022-05-02T03:24:48.721222+00:00
[2022-05-02 06:50:42,810] {taskinstance.py:1700} ERROR - Task failed with exception
Traceback (most recent call last):
  File "/home/airflow/.local/lib/python3.7/site-packages/airflow/models/taskinstance.py", line 1329, in _run_raw_task
    self._execute_task_with_callbacks(context)
  File "/home/airflow/.local/lib/python3.7/site-packages/airflow/models/taskinstance.py", line 1455, in _execute_task_with_callbacks
    result = self._execute_task(context, self.task)
  File "/home/airflow/.local/lib/python3.7/site-packages/airflow/models/taskinstance.py", line 1511, in _execute_task
    result = execute_callable(context=context)
  File "/home/airflow/.local/lib/python3.7/site-packages/airflow/operators/python.py", line 174, in execute
    return_value = self.execute_callable()
  File "/home/airflow/.local/lib/python3.7/site-packages/airflow/operators/python.py", line 185, in execute_callable
    return self.python_callable(*self.op_args, **self.op_kwargs)
  File "/opt/airflow/dags/gcs_to_bq_task.py", line 92, in process_data
    df_emp = spark.read.option("header", "true").parquet('gs://de-project-data-lake_intense-glow-347320/raw/*')
  File "/home/airflow/.local/lib/python3.7/site-packages/pyspark/sql/readwriter.py", line 301, in parquet
    return self._df(self._jreader.parquet(_to_seq(self._spark._sc, paths)))
  File "/home/airflow/.local/lib/python3.7/site-packages/py4j/java_gateway.py", line 1322, in __call__
    answer, self.gateway_client, self.target_id, self.name)
  File "/home/airflow/.local/lib/python3.7/site-packages/pyspark/sql/utils.py", line 111, in deco
    return f(*a, **kw)
  File "/home/airflow/.local/lib/python3.7/site-packages/py4j/protocol.py", line 328, in get_return_value
    format(target_id, ".", name), value)
py4j.protocol.Py4JJavaError: An error occurred while calling o102.parquet.
: org.apache.hadoop.fs.UnsupportedFileSystemException: No FileSystem for scheme "gs"
	at org.apache.hadoop.fs.FileSystem.getFileSystemClass(FileSystem.java:3443)
	at org.apache.hadoop.fs.FileSystem.createFileSystem(FileSystem.java:3466)
	at org.apache.hadoop.fs.FileSystem.access$300(FileSystem.java:174)
	at org.apache.hadoop.fs.FileSystem$Cache.getInternal(FileSystem.java:3574)
	at org.apache.hadoop.fs.FileSystem$Cache.get(FileSystem.java:3521)
	at org.apache.hadoop.fs.FileSystem.get(FileSystem.java:540)
	at org.apache.hadoop.fs.Path.getFileSystem(Path.java:365)
	at org.apache.spark.sql.execution.datasources.DataSource$.$anonfun$checkAndGlobPathIfNecessary$1(DataSource.scala:747)
	at scala.collection.immutable.List.map(List.scala:293)
	at org.apache.spark.sql.execution.datasources.DataSource$.checkAndGlobPathIfNecessary(DataSource.scala:745)
	at org.apache.spark.sql.execution.datasources.DataSource.checkAndGlobPathIfNecessary(DataSource.scala:577)
	at org.apache.spark.sql.execution.datasources.DataSource.resolveRelation(DataSource.scala:408)
	at org.apache.spark.sql.DataFrameReader.loadV1Source(DataFrameReader.scala:274)
	at org.apache.spark.sql.DataFrameReader.$anonfun$load$3(DataFrameReader.scala:245)
	at scala.Option.getOrElse(Option.scala:189)
	at org.apache.spark.sql.DataFrameReader.load(DataFrameReader.scala:245)
	at org.apache.spark.sql.DataFrameReader.parquet(DataFrameReader.scala:596)
	at java.base/jdk.internal.reflect.NativeMethodAccessorImpl.invoke0(Native Method)
	at java.base/jdk.internal.reflect.NativeMethodAccessorImpl.invoke(NativeMethodAccessorImpl.java:62)
	at java.base/jdk.internal.reflect.DelegatingMethodAccessorImpl.invoke(DelegatingMethodAccessorImpl.java:43)
	at java.base/java.lang.reflect.Method.invoke(Method.java:566)
	at py4j.reflection.MethodInvoker.invoke(MethodInvoker.java:244)
	at py4j.reflection.ReflectionEngine.invoke(ReflectionEngine.java:357)
	at py4j.Gateway.invoke(Gateway.java:282)
	at py4j.commands.AbstractCommand.invokeMethod(AbstractCommand.java:132)
	at py4j.commands.CallCommand.execute(CallCommand.java:79)
	at py4j.ClientServerConnection.waitForCommands(ClientServerConnection.java:182)
	at py4j.ClientServerConnection.run(ClientServerConnection.java:106)
	at java.base/java.lang.Thread.run(Thread.java:829)

[2022-05-02 06:50:42,929] {taskinstance.py:1277} INFO - Marking task as UP_FOR_RETRY. dag_id=gcs_to_bq_dag, task_id=process_data_from_gcs_task, execution_date=20220502T032448, start_date=20220502T065020, end_date=20220502T065042
[2022-05-02 06:50:42,976] {standard_task_runner.py:92} ERROR - Failed to execute job 817 for task process_data_from_gcs_task
Traceback (most recent call last):
  File "/home/airflow/.local/lib/python3.7/site-packages/airflow/task/task_runner/standard_task_runner.py", line 85, in _start_by_fork
    args.func(args, dag=self.dag)
  File "/home/airflow/.local/lib/python3.7/site-packages/airflow/cli/cli_parser.py", line 48, in command
    return func(*args, **kwargs)
  File "/home/airflow/.local/lib/python3.7/site-packages/airflow/utils/cli.py", line 92, in wrapper
    return f(*args, **kwargs)
  File "/home/airflow/.local/lib/python3.7/site-packages/airflow/cli/commands/task_command.py", line 298, in task_run
    _run_task_by_selected_method(args, dag, ti)
  File "/home/airflow/.local/lib/python3.7/site-packages/airflow/cli/commands/task_command.py", line 107, in _run_task_by_selected_method
    _run_raw_task(args, ti)
  File "/home/airflow/.local/lib/python3.7/site-packages/airflow/cli/commands/task_command.py", line 184, in _run_raw_task
    error_file=args.error_file,
  File "/home/airflow/.local/lib/python3.7/site-packages/airflow/utils/session.py", line 70, in wrapper
    return func(*args, session=session, **kwargs)
  File "/home/airflow/.local/lib/python3.7/site-packages/airflow/models/taskinstance.py", line 1329, in _run_raw_task
    self._execute_task_with_callbacks(context)
  File "/home/airflow/.local/lib/python3.7/site-packages/airflow/models/taskinstance.py", line 1455, in _execute_task_with_callbacks
    result = self._execute_task(context, self.task)
  File "/home/airflow/.local/lib/python3.7/site-packages/airflow/models/taskinstance.py", line 1511, in _execute_task
    result = execute_callable(context=context)
  File "/home/airflow/.local/lib/python3.7/site-packages/airflow/operators/python.py", line 174, in execute
    return_value = self.execute_callable()
  File "/home/airflow/.local/lib/python3.7/site-packages/airflow/operators/python.py", line 185, in execute_callable
    return self.python_callable(*self.op_args, **self.op_kwargs)
  File "/opt/airflow/dags/gcs_to_bq_task.py", line 92, in process_data
    df_emp = spark.read.option("header", "true").parquet('gs://de-project-data-lake_intense-glow-347320/raw/*')
  File "/home/airflow/.local/lib/python3.7/site-packages/pyspark/sql/readwriter.py", line 301, in parquet
    return self._df(self._jreader.parquet(_to_seq(self._spark._sc, paths)))
  File "/home/airflow/.local/lib/python3.7/site-packages/py4j/java_gateway.py", line 1322, in __call__
    answer, self.gateway_client, self.target_id, self.name)
  File "/home/airflow/.local/lib/python3.7/site-packages/pyspark/sql/utils.py", line 111, in deco
    return f(*a, **kw)
  File "/home/airflow/.local/lib/python3.7/site-packages/py4j/protocol.py", line 328, in get_return_value
    format(target_id, ".", name), value)
py4j.protocol.Py4JJavaError: An error occurred while calling o102.parquet.
: org.apache.hadoop.fs.UnsupportedFileSystemException: No FileSystem for scheme "gs"
	at org.apache.hadoop.fs.FileSystem.getFileSystemClass(FileSystem.java:3443)
	at org.apache.hadoop.fs.FileSystem.createFileSystem(FileSystem.java:3466)
	at org.apache.hadoop.fs.FileSystem.access$300(FileSystem.java:174)
	at org.apache.hadoop.fs.FileSystem$Cache.getInternal(FileSystem.java:3574)
	at org.apache.hadoop.fs.FileSystem$Cache.get(FileSystem.java:3521)
	at org.apache.hadoop.fs.FileSystem.get(FileSystem.java:540)
	at org.apache.hadoop.fs.Path.getFileSystem(Path.java:365)
	at org.apache.spark.sql.execution.datasources.DataSource$.$anonfun$checkAndGlobPathIfNecessary$1(DataSource.scala:747)
	at scala.collection.immutable.List.map(List.scala:293)
	at org.apache.spark.sql.execution.datasources.DataSource$.checkAndGlobPathIfNecessary(DataSource.scala:745)
	at org.apache.spark.sql.execution.datasources.DataSource.checkAndGlobPathIfNecessary(DataSource.scala:577)
	at org.apache.spark.sql.execution.datasources.DataSource.resolveRelation(DataSource.scala:408)
	at org.apache.spark.sql.DataFrameReader.loadV1Source(DataFrameReader.scala:274)
	at org.apache.spark.sql.DataFrameReader.$anonfun$load$3(DataFrameReader.scala:245)
	at scala.Option.getOrElse(Option.scala:189)
	at org.apache.spark.sql.DataFrameReader.load(DataFrameReader.scala:245)
	at org.apache.spark.sql.DataFrameReader.parquet(DataFrameReader.scala:596)
	at java.base/jdk.internal.reflect.NativeMethodAccessorImpl.invoke0(Native Method)
	at java.base/jdk.internal.reflect.NativeMethodAccessorImpl.invoke(NativeMethodAccessorImpl.java:62)
	at java.base/jdk.internal.reflect.DelegatingMethodAccessorImpl.invoke(DelegatingMethodAccessorImpl.java:43)
	at java.base/java.lang.reflect.Method.invoke(Method.java:566)
	at py4j.reflection.MethodInvoker.invoke(MethodInvoker.java:244)
	at py4j.reflection.ReflectionEngine.invoke(ReflectionEngine.java:357)
	at py4j.Gateway.invoke(Gateway.java:282)
	at py4j.commands.AbstractCommand.invokeMethod(AbstractCommand.java:132)
	at py4j.commands.CallCommand.execute(CallCommand.java:79)
	at py4j.ClientServerConnection.waitForCommands(ClientServerConnection.java:182)
	at py4j.ClientServerConnection.run(ClientServerConnection.java:106)
	at java.base/java.lang.Thread.run(Thread.java:829)

[2022-05-02 06:50:43,032] {local_task_job.py:154} INFO - Task exited with return code 1
[2022-05-02 06:50:43,265] {local_task_job.py:264} INFO - 0 downstream tasks scheduled from follow-on schedule check
